Traceback (most recent call last):
  File "/Users/humphreyyang/anaconda3/envs/quantecon/lib/python3.9/site-packages/jupyter_cache/executors/utils.py", line 58, in single_nb_execution
    executenb(
  File "/Users/humphreyyang/anaconda3/envs/quantecon/lib/python3.9/site-packages/nbclient/client.py", line 1204, in execute
    return NotebookClient(nb=nb, resources=resources, km=km, **kwargs).execute()
  File "/Users/humphreyyang/anaconda3/envs/quantecon/lib/python3.9/site-packages/nbclient/util.py", line 84, in wrapped
    return just_run(coro(*args, **kwargs))
  File "/Users/humphreyyang/anaconda3/envs/quantecon/lib/python3.9/site-packages/nbclient/util.py", line 62, in just_run
    return loop.run_until_complete(coro)
  File "/Users/humphreyyang/anaconda3/envs/quantecon/lib/python3.9/asyncio/base_events.py", line 647, in run_until_complete
    return future.result()
  File "/Users/humphreyyang/anaconda3/envs/quantecon/lib/python3.9/site-packages/nbclient/client.py", line 663, in async_execute
    await self.async_execute_cell(
  File "/Users/humphreyyang/anaconda3/envs/quantecon/lib/python3.9/site-packages/nbclient/client.py", line 965, in async_execute_cell
    await self._check_raise_for_error(cell, cell_index, exec_reply)
  File "/Users/humphreyyang/anaconda3/envs/quantecon/lib/python3.9/site-packages/nbclient/client.py", line 862, in _check_raise_for_error
    raise CellExecutionError.from_cell_and_msg(cell, exec_reply_content)
nbclient.exceptions.CellExecutionError: An error occurred while executing the following cell:
------------------
from scipy.optimize import minimize_scalar

def objective(q):
    return -W(q, market)

result = minimize_scalar(objective, bounds=(0, 10))
print(result.message)
------------------

[0;31m---------------------------------------------------------------------------[0m
[0;31mKeyError[0m                                  Traceback (most recent call last)
File [0;32m~/anaconda3/envs/quantecon/lib/python3.9/site-packages/scipy/optimize/optimize.py:122[0m, in [0;36mOptimizeResult.__getattr__[0;34m(self, name)[0m
[1;32m    121[0m [38;5;28;01mtry[39;00m:
[0;32m--> 122[0m     [38;5;28;01mreturn[39;00m [38;5;28;43mself[39;49m[43m[[49m[43mname[49m[43m][49m
[1;32m    123[0m [38;5;28;01mexcept[39;00m [38;5;167;01mKeyError[39;00m [38;5;28;01mas[39;00m e:

[0;31mKeyError[0m: 'message'

The above exception was the direct cause of the following exception:

[0;31mAttributeError[0m                            Traceback (most recent call last)
Cell [0;32mIn[14], line 7[0m
[1;32m      4[0m     [38;5;28;01mreturn[39;00m [38;5;241m-[39mW(q, market)
[1;32m      6[0m result [38;5;241m=[39m minimize_scalar(objective, bounds[38;5;241m=[39m([38;5;241m0[39m, [38;5;241m10[39m))
[0;32m----> 7[0m [38;5;28mprint[39m([43mresult[49m[38;5;241;43m.[39;49m[43mmessage[49m)

File [0;32m~/anaconda3/envs/quantecon/lib/python3.9/site-packages/scipy/optimize/optimize.py:124[0m, in [0;36mOptimizeResult.__getattr__[0;34m(self, name)[0m
[1;32m    122[0m     [38;5;28;01mreturn[39;00m [38;5;28mself[39m[name]
[1;32m    123[0m [38;5;28;01mexcept[39;00m [38;5;167;01mKeyError[39;00m [38;5;28;01mas[39;00m e:
[0;32m--> 124[0m     [38;5;28;01mraise[39;00m [38;5;167;01mAttributeError[39;00m(name) [38;5;28;01mfrom[39;00m [38;5;21;01me[39;00m

[0;31mAttributeError[0m: message
AttributeError: message

